Workbook

Sheet PRICING CALCULATOR
A1: CARE N TOUR - Medical Tourism Pricing Calculator
A2: Premium Medical Care in Egypt
A4: QUOTE INFORMATION
A5: Quote Date: | B5: =TODAY() -> 46039 | D5: Quote Number: | E5: QT-2026-001 | G5: Client Type: | H5: B2C
A6: Patient Name: | B6: Mohamed Alaa | D6: Country of Origin: | E6: Egypt | G6: Age: | H6: 40
A8: MEDICAL PROCEDURE
A9: Procedure Name: | B9: ICSI | E9: Hospital Tier: | F9: Premium
A10: Medical Cost (EGP): | B10: 45000 | C10: → USD: | D10: =B10*'Currency Rates'!$B$5 -> 900 | E10: Length of Stay: | F10: 10 | G10: nights
A12: ACCOMMODATION
A13: Hotel Category: | B13: 5-Star | C13: Room Type: | D13: Standard Room | E13: Meal Plan: | F13: All Inclusive
A14: Cost per Night (EGP): | B14: 5000 | C14: Nights: | D14: =F10 -> 10 | E14: Total (EGP): | F14: =B14*D14 -> 50000 | G14: → USD: | H14: =F14*'Currency Rates'!$B$5 -> 1000
A15: Meal Plan Cost (EGP/day): | B15: 3000 | C15: Days: | D15: =F10 -> 10 | E15: Total (EGP): | F15: =B15*D15 -> 30000 | G15: → USD: | H15: =F15*'Currency Rates'!$B$5 -> 600
A17: TRANSPORTATION
A18: Flight Cost (USD): | B18: 800 | C18: Origin: | F18: Flight Type: | G18: Round Trip
A19: Airport Transfers (EGP): | B19: 5000 | C19: → USD: | D19: =B19*'Currency Rates'!$B$5 -> 100 | E19: Vehicle Type: | F19: Standard Car
A20: Local Transport (EGP): | B20: 5000 | C20: → USD: | D20: =B20*'Currency Rates'!$B$5 -> 100 | E20: Days Needed: | F20: 20
A22: TOURISM & ADDITIONAL SERVICES
A23: Service Name | B23: Quantity | C23: Unit Cost (EGP) | D23: Unit Cost (USD) | E23: Total (EGP) | F23: Total (USD)
A24: Nile cruise | B24: 0 | C24: 7000 | D24: =C24*'Currency Rates'!$B$5 -> 140 | E24: =B24*C24 -> 0 | F24: =E24*'Currency Rates'!$B$5 -> 0
B25: 0 | C25: 0 | D25: =C25*'Currency Rates'!$B$5 -> 0 | E25: =B25*C25 -> 0 | F25: =E25*'Currency Rates'!$B$5 -> 0
B26: 0 | C26: 0 | D26: =C26*'Currency Rates'!$B$5 -> 0 | E26: =B26*C26 -> 0 | F26: =E26*'Currency Rates'!$B$5 -> 0
B27: 0 | C27: 0 | D27: =C27*'Currency Rates'!$B$5 -> 0 | E27: =B27*C27 -> 0 | F27: =E27*'Currency Rates'!$B$5 -> 0
B28: 0 | C28: 0 | D28: =C28*'Currency Rates'!$B$5 -> 0 | E28: =B28*C28 -> 0 | F28: =E28*'Currency Rates'!$B$5 -> 0
A29: Total Extras: | E29: =SUM(E24:E28) -> 0 | F29: =SUM(F24:F28) -> 0
A31: COST SUMMARY
A32: Medical Procedure Cost | B32: =D10 -> 900 | D32: EGP: | E32: =B10 -> 45000
A33: Accommodation (Hotel + Meals) | B33: =H14+H15 -> 1600 | D33: EGP: | E33: =F14+F15 -> 80000
A34: Transportation (Flight + Local) | B34: =B18+D19+D20 -> 1000 | D34: EGP: | E34: =(B19+B20) -> 10000
A35: Tourism & Additional Services | B35: =F29 -> 0 | D35: EGP: | E35: =E29 -> 0
A36: Indirect Cost per Patient | B36: ='Indirect Costs'!D15 -> 586
A37: SUBTOTAL (Direct + Indirect Costs) | B37: =SUM(B32:B36) -> 4086
A39: PROFIT MARGIN & FINAL PRICE
A40: Profit Margin %: | B40: =IF(H5="B2B",0.35,0.5) -> 0.5 | C40: (B2B: 35% | B2C: 50-65%)
A41: Profit Amount: | B41: =B37*B40 -> 2043
A43: FINAL PRICE (USD) | D43: =B37+B41 -> 6129

Sheet Medical Procedures
A1: Procedure Code | B1: Procedure Name | C1: Category | D1: Premium Hospital (EGP) | E1: Mid-Range Hospital (EGP) | F1: Budget Hospital (EGP) | G1: Typical Length of Stay (nights) | H1: Pre-Op Days | I1: Post-Op Days | J1: Notes
A2: P001 | C2: Cosmetic Surgery
A3: P002 | C3: Dental
A4: P003 | C4: Orthopedic
A5: P004 | C5: Cardiac
A6: P005 | C6: Fertility
A7: P006 | C7: Ophthalmology
A8: P007 | C8: Bariatric
A9: P008 | C9: General Surgery
A10: P009 | C10: Cancer Treatment
A11: P010 | C11: Diagnostics

Sheet Accommodation
A1: Hotel Code | B1: Hotel Name | C1: Star Rating | D1: Location | E1: Room Type | F1: Price per Night (EGP) | G1: Meal Plan | H1: Meal Plan Cost (EGP/day) | I1: Airport Distance (km) | J1: Notes
A2: H001 | B2: Premium Hotel - Cairo | C2: 5-Star | D2: Cairo | E2: Standard Room | F2: 2500 | G2: Breakfast | H2: 300 | I2: 25
A3: H002 | B3: Premium Hotel - Cairo | C3: 5-Star | D3: Cairo | E3: Deluxe Room | F3: 3500 | G3: Half Board | H3: 600 | I3: 25
A4: H003 | B4: Mid-Range Hotel - Cairo | C4: 4-Star | D4: Cairo | E4: Standard Room | F4: 1500 | G4: Breakfast | H4: 200 | I4: 20
A5: H004 | B5: Mid-Range Hotel - Cairo | C5: 4-Star | D5: Cairo | E5: Suite | F5: 2200 | G5: Full Board | H5: 800 | I5: 20
A6: H005 | B6: Budget Hotel - Cairo | C6: 3-Star | D6: Cairo | E6: Standard Room | F6: 800 | G6: Breakfast | H6: 150 | I6: 30
A7: H006 | B7: Budget Hotel - Cairo | C7: 3-Star | D7: Cairo | E7: Twin Room | F7: 1000 | G7: Half Board | H7: 400 | I7: 30
A8: H007 | B8: Premium Hotel - Giza | C8: 5-Star | D8: Giza | E8: Pyramid View | F8: 4000 | G8: All Inclusive | H8: 1200 | I8: 40
A9: H008 | B9: Mid-Range Hotel - Giza | C9: 4-Star | D9: Giza | E9: Standard Room | F9: 1800 | G9: Breakfast | H9: 250 | I9: 35

Sheet Transportation
A1: Service Type | B1: Description | C1: Route/Details | D1: Vehicle Type | E1: Cost (EGP) | F1: Cost (USD) | G1: Cost (EUR) | H1: Provider | I1: Notes
A2: Airport Transfer | B2: Airport to Hotel (One Way) | C2: Cairo Airport - Hotel | D2: Standard Car | E2: 400 | F2: 13 | G2: 12
A3: Airport Transfer | B3: Airport to Hotel (One Way) | C3: Cairo Airport - Hotel | D3: Luxury Car | E3: 800 | F3: 26 | G3: 24
A4: Airport Transfer | B4: Airport to Hotel (Round Trip) | C4: Cairo Airport - Hotel | D4: Standard Car | E4: 700 | F4: 23 | G4: 21
A5: Airport Transfer | B5: Airport to Hotel (Round Trip) | C5: Cairo Airport - Hotel | D5: Luxury Car | E5: 1400 | F5: 45 | G5: 42
A6: Local Transport | B6: Daily Car Rental | C6: Within Cairo | D6: Standard Car + Driver | E6: 1200 | F6: 39 | G6: 36 | I6: 8 hours
A7: Local Transport | B7: Hospital Transfers | C7: Hotel to Hospital (per trip) | D7: Standard Car | E7: 250 | F7: 8 | G7: 7.5
A8: Flight Estimate | B8: Europe to Cairo | C8: Average Economy | D8: Commercial | F8: 400 | G8: 370 | I8: Round trip
A9: Flight Estimate | B9: Middle East to Cairo | C9: Average Economy | D9: Commercial | F9: 250 | G9: 230 | I9: Round trip
A10: Flight Estimate | B10: North America to Cairo | C10: Average Economy | D10: Commercial | F10: 800 | G10: 740 | I10: Round trip
A11: Flight Estimate | B11: Africa to Cairo | C11: Average Economy | D11: Commercial | F11: 350 | G11: 320 | I11: Round trip

Sheet Tourism & Extras
A1: Service Code | B1: Service Name | C1: Category | D1: Description | E1: Duration | F1: Cost (EGP) | G1: Cost (USD) | H1: Cost (EUR) | I1: Max Persons | J1: Notes
A2: T001 | B2: Pyramids & Sphinx Tour | C2: Sightseeing | D2: Giza Pyramids, Sphinx, Museum | E2: Half Day | F2: 1200 | G2: 39 | H2: 36 | I2: 4
A3: T002 | B3: Full Day Cairo Tour | C3: Sightseeing | D3: Pyramids, Egyptian Museum, Khan el-Khalili | E3: Full Day | F3: 2000 | G3: 65 | H3: 60 | I3: 4
A4: T003 | B4: Nile Dinner Cruise | C4: Entertainment | D4: Dinner cruise with show | E4: 3 hours | F4: 1500 | G4: 48 | H4: 45 | I4: 2
A5: T004 | B5: Luxor Day Trip | C5: Sightseeing | D5: Valley of Kings, Karnak Temple (flight) | E5: Full Day | F5: 6500 | G5: 210 | H5: 195 | I5: 2 | J5: Includes flights
A6: T005 | B6: Alexandria Day Trip | C6: Sightseeing | D6: Library, Citadel, Montazah | E6: Full Day | F6: 2500 | G6: 81 | H6: 75 | I6: 4
A7: T006 | B7: Desert Safari | C7: Adventure | D7: Quad biking, camel ride, BBQ dinner | E7: Half Day | F7: 1800 | G7: 58 | H7: 54 | I7: 4
A8: E001 | B8: Medical Translator | C8: Support Service | D8: Professional medical translator | E8: Per Day | F8: 800 | G8: 26 | H8: 24
A9: E002 | B9: Private Nurse | C9: Medical Support | D9: 24hr private nursing care | E9: Per Day | F9: 1500 | G9: 48 | H9: 45
A10: E003 | B10: Companion Accommodation | C10: Support | D10: Additional room for companion | E10: Per Night | F10: 600 | G10: 19 | H10: 18
A11: E004 | B11: Visa Assistance | C11: Documentation | D11: Complete visa processing support | E11: One Time | F11: 500 | G11: 16 | H11: 15
A12: E005 | B12: SIM Card & Internet | C12: Communication | D12: Local SIM with data package | E12: One Time | F12: 300 | G12: 10 | H12: 9
A13: E006 | B13: Medical Records Translation | C13: Documentation | D13: Professional medical document translation | E13: Per Document | F13: 400 | G13: 13 | H13: 12

Sheet Indirect Costs
A1: Annual Indirect Costs Overview
A3: Cost Category | B3: Annual Cost (USD) | C3: Monthly Cost (USD) | D3: Per Patient Allocation | E3: Notes
A4: Marketing & Advertising | B4: 50000 | C4: =B4/12 -> 4166.6667 | D4: =B4/$B$18 -> 100 | E4: Digital ads, SEO, content marketing
A5: Staff Salaries | B5: 120000 | C5: =B5/12 -> 10000 | D5: =B5/$B$18 -> 240 | E5: Coordinators, admin, customer service
A6: Office Rent & Utilities | B6: 24000 | C6: =B6/12 -> 2000 | D6: =B6/$B$18 -> 48 | E6: Office space, electricity, internet
A7: Insurance & Legal | B7: 18000 | C7: =B7/12 -> 1500 | D7: =B7/$B$18 -> 36 | E7: Business insurance, legal fees
A8: Technology & Software | B8: 12000 | C8: =B8/12 -> 1000 | D8: =B8/$B$18 -> 24 | E8: CRM, booking systems, website
A9: Commission to Agents | B9: 30000 | C9: =B9/12 -> 2500 | D9: =B9/$B$18 -> 60 | E9: Referral fees, partnerships
A10: Quality Control & Accreditation | B10: 8000 | C10: =B10/12 -> 666.66667 | D10: =B10/$B$18 -> 16 | E10: Audits, certifications
A11: Customer Support & Follow-up | B11: 15000 | C11: =B11/12 -> 1250 | D11: =B11/$B$18 -> 30 | E11: Post-treatment care coordination
A12: Training & Development | B12: 6000 | C12: =B12/12 -> 500 | D12: =B12/$B$18 -> 12 | E12: Staff training programs
A13: Contingency Fund | B13: 10000 | C13: =B13/12 -> 833.33333 | D13: =B13/$B$18 -> 20 | E13: Emergency situations, refunds
A15: TOTAL ANNUAL INDIRECT COSTS | B15: =SUM(B4:B13) -> 293000 | C15: =SUM(C4:C13) -> 24416.667 | D15: =SUM(D4:D13) -> 586 | E15: Based on 250 patients/year
A17: Note: | B17: Adjust "Per Patient Allocation" formula based on your projected annual patient volume.
A18: Expected Annual Patient Volume: | B18: 500 | C18: patients

Sheet Currency Rates
A1: Currency Exchange Rates - Update Regularly
A2: Last Updated: 2026-01-12
A4: Currency | B4: Rate to USD | C4: USD to Currency | D4: Notes
A5: EGP (Egyptian Pound) | B5: =1/C5 -> 0.02 | C5: 50 | D5: Update daily - highly volatile
A6: EUR (Euro) | B6: =1/C6 -> 0.017857143 | C6: 56 | D6: Update weekly
A7: GBP (British Pound) | B7: =1/C7 -> 0.014285714 | C7: 70 | D7: Update weekly
A8: SAR (Saudi Riyal) | B8: =1/C8 -> 0.066666667 | C8: 15 | D8: Update monthly
A9: AED (UAE Dirham) | B9: =1/C9 -> 0.066666667 | C9: 15 | D9: Update monthly

Sheet Quote Generator
A1: CARE N TOUR
A2: Premium Medical Tourism in Egypt
A3: www.carentour.com | info@carentour.com | +20 122 9503333
A6: MEDICAL TOURISM PACKAGE QUOTATION
A8: PATIENT INFORMATION
A9: Quote Number: | B9: ='PRICING CALCULATOR'!E5 -> QT-2026-001 | D9: Quote Date: | E9: ='PRICING CALCULATOR'!B5 -> 46039
A10: Patient Name: | B10: ='PRICING CALCULATOR'!B6 -> Mohamed Alaa | D10: Country: | E10: ='PRICING CALCULATOR'!E6 -> Egypt
A11: Age: | B11: ='PRICING CALCULATOR'!H6 -> 40 | D11: Client Type: | E11: ='PRICING CALCULATOR'!H5 -> B2C
A13: MEDICAL PROCEDURE DETAILS
A14: Procedure: | B14: ='PRICING CALCULATOR'!B9 -> ICSI | E14: Hospital Tier: | F14: ='PRICING CALCULATOR'!F9 -> Premium
A15: Length of Stay:
A17: PACKAGE INCLUSIONS
A18: ✓ Complete Medical Procedure | B18: ='PRICING CALCULATOR'!D9 -> 0 | E18: USD
A19: ✓ Hospital Stay & Medical Care | B19: Included
A20: ✓ Accommodation | B20: ='PRICING CALCULATOR'!F10 -> 10
A21: ✓ All Meals | B21: ='PRICING CALCULATOR'!F13 -> All Inclusive
A22: ✓ International Flights | B22: ='PRICING CALCULATOR'!D18 -> 0
A23: ✓ Airport Transfers | B23: Round Trip
A24: ✓ Local Transportation | B24: As Required
A25: ✓ 24/7 Medical Coordinator | B25: Complete Journey Support | E25: Included
A26: ✓ Pre & Post-Op Consultations | B26: Included
A27: ✓ Medical Records & Documentation | B27: Included
A29: ADDITIONAL SERVICES
A30: ='PRICING CALCULATOR'!A23 -> Service Name | B30: ='PRICING CALCULATOR'!B23 -> Quantity | C30: x | D30: ='PRICING CALCULATOR'!D23 -> Unit Cost (USD) | E30: = | F30: ='PRICING CALCULATOR'!F23 -> Total (USD)
A31: ='PRICING CALCULATOR'!A24 -> Nile cruise | B31: ='PRICING CALCULATOR'!B24 -> 0 | C31: x | D31: ='PRICING CALCULATOR'!D24 -> 140 | E31: = | F31: ='PRICING CALCULATOR'!F24 -> 0
A32: ='PRICING CALCULATOR'!A25 -> 0 | B32: ='PRICING CALCULATOR'!B25 -> 0 | C32: x | D32: ='PRICING CALCULATOR'!D25 -> 0 | E32: = | F32: ='PRICING CALCULATOR'!F25 -> 0
A33: ='PRICING CALCULATOR'!A26 -> 0 | B33: ='PRICING CALCULATOR'!B26 -> 0 | C33: x | D33: ='PRICING CALCULATOR'!D26 -> 0 | E33: = | F33: ='PRICING CALCULATOR'!F26 -> 0
A34: ='PRICING CALCULATOR'!A27 -> 0 | B34: ='PRICING CALCULATOR'!B27 -> 0 | C34: x | D34: ='PRICING CALCULATOR'!D27 -> 0 | E34: = | F34: ='PRICING CALCULATOR'!F27 -> 0
A36: INVESTMENT SUMMARY
A37: Package Subtotal: | E37: ='PRICING CALCULATOR'!B36 -> 586
A39: TOTAL PACKAGE PRICE | E39: ='PRICING CALCULATOR'!D43 -> 6129
A41: PAYMENT TERMS
A42: • 30% deposit required upon booking confirmation
A43: • 50% payment due 14 days before arrival
A44: • Final 20% payment upon arrival in Egypt
A45: • Accepted payment methods: Bank transfer, Credit card, PayPal
A47: WHY CHOOSE CARE N TOUR?
A48: ✓ JCI Accredited Hospitals - International quality standards
A49: ✓ 200+ Board-Certified Specialists - Internationally trained surgeons
A50: ✓ Up to 70% Cost Savings - Compared to US/Europe prices
...
